[2024-04-13T18:52:03.757+0000] {local_task_job_runner.py:120} INFO - ::group::Pre task execution logs
[2024-04-13T18:52:03.797+0000] {taskinstance.py:2073} INFO - Dependencies all met for dep_context=non-requeueable deps ti=<TaskInstance: fruits_data_pipeline.create_fruits_table manual__2024-04-13T18:45:03.085738+00:00 [queued]>
[2024-04-13T18:52:03.840+0000] {taskinstance.py:2073} INFO - Dependencies all met for dep_context=requeueable deps ti=<TaskInstance: fruits_data_pipeline.create_fruits_table manual__2024-04-13T18:45:03.085738+00:00 [queued]>
[2024-04-13T18:52:03.842+0000] {taskinstance.py:2303} INFO - Starting attempt 4 of 4
[2024-04-13T18:52:03.921+0000] {taskinstance.py:2327} INFO - Executing <Task(PythonOperator): create_fruits_table> on 2024-04-13 18:45:03.085738+00:00
[2024-04-13T18:52:03.961+0000] {warnings.py:110} WARNING - /home/***/.local/lib/python3.12/site-packages/***/task/task_runner/standard_task_runner.py:61: DeprecationWarning: This process (pid=666) is multi-threaded, use of fork() may lead to deadlocks in the child.
  pid = os.fork()

[2024-04-13T18:52:03.966+0000] {standard_task_runner.py:63} INFO - Started process 668 to run task
[2024-04-13T18:52:03.967+0000] {standard_task_runner.py:90} INFO - Running: ['***', 'tasks', 'run', 'fruits_data_pipeline', 'create_fruits_table', 'manual__2024-04-13T18:45:03.085738+00:00', '--job-id', '246', '--raw', '--subdir', 'DAGS_FOLDER/eksplorasii_dag.py', '--cfg-path', '/tmp/tmpvp4wnzww']
[2024-04-13T18:52:03.977+0000] {standard_task_runner.py:91} INFO - Job 246: Subtask create_fruits_table
[2024-04-13T18:52:04.200+0000] {task_command.py:426} INFO - Running <TaskInstance: fruits_data_pipeline.create_fruits_table manual__2024-04-13T18:45:03.085738+00:00 [running]> on host 2354a2c4893f
[2024-04-13T18:52:04.596+0000] {taskinstance.py:2644} INFO - Exporting env vars: AIRFLOW_CTX_DAG_OWNER='abdan' AIRFLOW_CTX_DAG_ID='fruits_data_pipeline' AIRFLOW_CTX_TASK_ID='create_fruits_table' AIRFLOW_CTX_EXECUTION_DATE='2024-04-13T18:45:03.085738+00:00' AIRFLOW_CTX_TRY_NUMBER='4' AIRFLOW_CTX_DAG_RUN_ID='manual__2024-04-13T18:45:03.085738+00:00'
[2024-04-13T18:52:04.600+0000] {taskinstance.py:430} INFO - ::endgroup::
[2024-04-13T18:52:04.609+0000] {taskinstance.py:441} INFO - ::group::Post task execution logs
[2024-04-13T18:52:04.610+0000] {taskinstance.py:2890} ERROR - Task failed with exception
Traceback (most recent call last):
  File "/home/airflow/.local/lib/python3.12/site-packages/airflow/models/taskinstance.py", line 465, in _execute_task
    result = _execute_callable(context=context, **execute_callable_kwargs)
             ^^^^^^^^^^^^^^^^^^^^^^^^^^^^^^^^^^^^^^^^^^^^^^^^^^^^^^^^^^^^^
  File "/home/airflow/.local/lib/python3.12/site-packages/airflow/models/taskinstance.py", line 432, in _execute_callable
    return execute_callable(context=context, **execute_callable_kwargs)
           ^^^^^^^^^^^^^^^^^^^^^^^^^^^^^^^^^^^^^^^^^^^^^^^^^^^^^^^^^^^^
  File "/home/airflow/.local/lib/python3.12/site-packages/airflow/models/baseoperator.py", line 400, in wrapper
    return func(self, *args, **kwargs)
           ^^^^^^^^^^^^^^^^^^^^^^^^^^^
  File "/home/airflow/.local/lib/python3.12/site-packages/airflow/operators/python.py", line 235, in execute
    return_value = self.execute_callable()
                   ^^^^^^^^^^^^^^^^^^^^^^^
  File "/home/airflow/.local/lib/python3.12/site-packages/airflow/operators/python.py", line 252, in execute_callable
    return self.python_callable(*self.op_args, **self.op_kwargs)
           ^^^^^^^^^^^^^^^^^^^^^^^^^^^^^^^^^^^^^^^^^^^^^^^^^^^^^
  File "/opt/airflow/dags/eksplorasii_dag.py", line 26, in create_fruits_table
    conn = psycopg2.connect(
           ^^^^^^^^^^^^^^^^^
  File "/home/airflow/.local/lib/python3.12/site-packages/psycopg2/__init__.py", line 122, in connect
    conn = _connect(dsn, connection_factory=connection_factory, **kwasync)
           ^^^^^^^^^^^^^^^^^^^^^^^^^^^^^^^^^^^^^^^^^^^^^^^^^^^^^^^^^^^^^^^
psycopg2.OperationalError: connection to server at "localhost" (::1), port 5432 failed: Connection refused
	Is the server running on that host and accepting TCP/IP connections?
connection to server at "localhost" (127.0.0.1), port 5432 failed: Connection refused
	Is the server running on that host and accepting TCP/IP connections?

[2024-04-13T18:52:04.646+0000] {taskinstance.py:1205} INFO - Marking task as FAILED. dag_id=fruits_data_pipeline, task_id=create_fruits_table, execution_date=20240413T184503, start_date=20240413T185203, end_date=20240413T185204
[2024-04-13T18:52:04.705+0000] {standard_task_runner.py:110} ERROR - Failed to execute job 246 for task create_fruits_table (connection to server at "localhost" (::1), port 5432 failed: Connection refused
	Is the server running on that host and accepting TCP/IP connections?
connection to server at "localhost" (127.0.0.1), port 5432 failed: Connection refused
	Is the server running on that host and accepting TCP/IP connections?
; 668)
[2024-04-13T18:52:04.763+0000] {local_task_job_runner.py:240} INFO - Task exited with return code 1
[2024-04-13T18:52:04.808+0000] {taskinstance.py:3482} INFO - 0 downstream tasks scheduled from follow-on schedule check
[2024-04-13T18:52:04.820+0000] {local_task_job_runner.py:222} INFO - ::endgroup::
