[2024-04-12T00:30:21.694+0000] {local_task_job_runner.py:120} INFO - ::group::Pre task execution logs
[2024-04-12T00:30:21.739+0000] {taskinstance.py:2073} INFO - Dependencies all met for dep_context=non-requeueable deps ti=<TaskInstance: prioritas1_no1.touch_about_us scheduled__2024-04-11T00:00:00+00:00 [queued]>
[2024-04-12T00:30:21.750+0000] {taskinstance.py:2073} INFO - Dependencies all met for dep_context=requeueable deps ti=<TaskInstance: prioritas1_no1.touch_about_us scheduled__2024-04-11T00:00:00+00:00 [queued]>
[2024-04-12T00:30:21.751+0000] {taskinstance.py:2303} INFO - Starting attempt 5 of 6
[2024-04-12T00:30:21.778+0000] {taskinstance.py:2327} INFO - Executing <Task(BashOperator): touch_about_us> on 2024-04-11 00:00:00+00:00
[2024-04-12T00:30:21.791+0000] {warnings.py:110} WARNING - /home/***/.local/lib/python3.12/site-packages/***/task/task_runner/standard_task_runner.py:61: DeprecationWarning: This process (pid=246) is multi-threaded, use of fork() may lead to deadlocks in the child.
  pid = os.fork()

[2024-04-12T00:30:21.792+0000] {standard_task_runner.py:63} INFO - Started process 250 to run task
[2024-04-12T00:30:21.791+0000] {standard_task_runner.py:90} INFO - Running: ['***', 'tasks', 'run', 'prioritas1_no1', 'touch_about_us', 'scheduled__2024-04-11T00:00:00+00:00', '--job-id', '69', '--raw', '--subdir', 'DAGS_FOLDER/prioritas1_dag.py', '--cfg-path', '/tmp/tmph5z6z_ro']
[2024-04-12T00:30:21.794+0000] {standard_task_runner.py:91} INFO - Job 69: Subtask touch_about_us
[2024-04-12T00:30:21.882+0000] {task_command.py:426} INFO - Running <TaskInstance: prioritas1_no1.touch_about_us scheduled__2024-04-11T00:00:00+00:00 [running]> on host 805e8d5936d1
[2024-04-12T00:30:22.027+0000] {taskinstance.py:2644} INFO - Exporting env vars: AIRFLOW_CTX_DAG_OWNER='abdan' AIRFLOW_CTX_DAG_ID='prioritas1_no1' AIRFLOW_CTX_TASK_ID='touch_about_us' AIRFLOW_CTX_EXECUTION_DATE='2024-04-11T00:00:00+00:00' AIRFLOW_CTX_TRY_NUMBER='5' AIRFLOW_CTX_DAG_RUN_ID='scheduled__2024-04-11T00:00:00+00:00'
[2024-04-12T00:30:22.033+0000] {taskinstance.py:430} INFO - ::endgroup::
[2024-04-12T00:30:22.042+0000] {subprocess.py:63} INFO - Tmp dir root location: /tmp
[2024-04-12T00:30:22.044+0000] {subprocess.py:75} INFO - Running command: ['/usr/bin/bash', '-c', 'touch about_us/about.txt']
[2024-04-12T00:30:22.063+0000] {subprocess.py:86} INFO - Output:
[2024-04-12T00:30:22.095+0000] {subprocess.py:93} INFO - touch: cannot touch 'about_us/about.txt': No such file or directory
[2024-04-12T00:30:22.095+0000] {subprocess.py:97} INFO - Command exited with return code 1
[2024-04-12T00:30:22.097+0000] {taskinstance.py:441} INFO - ::group::Post task execution logs
[2024-04-12T00:30:22.117+0000] {taskinstance.py:2890} ERROR - Task failed with exception
Traceback (most recent call last):
  File "/home/airflow/.local/lib/python3.12/site-packages/airflow/models/taskinstance.py", line 465, in _execute_task
    result = _execute_callable(context=context, **execute_callable_kwargs)
             ^^^^^^^^^^^^^^^^^^^^^^^^^^^^^^^^^^^^^^^^^^^^^^^^^^^^^^^^^^^^^
  File "/home/airflow/.local/lib/python3.12/site-packages/airflow/models/taskinstance.py", line 432, in _execute_callable
    return execute_callable(context=context, **execute_callable_kwargs)
           ^^^^^^^^^^^^^^^^^^^^^^^^^^^^^^^^^^^^^^^^^^^^^^^^^^^^^^^^^^^^
  File "/home/airflow/.local/lib/python3.12/site-packages/airflow/models/baseoperator.py", line 400, in wrapper
    return func(self, *args, **kwargs)
           ^^^^^^^^^^^^^^^^^^^^^^^^^^^
  File "/home/airflow/.local/lib/python3.12/site-packages/airflow/operators/bash.py", line 243, in execute
    raise AirflowException(
airflow.exceptions.AirflowException: Bash command failed. The command returned a non-zero exit code 1.
[2024-04-12T00:30:22.127+0000] {taskinstance.py:1205} INFO - Marking task as UP_FOR_RETRY. dag_id=prioritas1_no1, task_id=touch_about_us, execution_date=20240411T000000, start_date=20240412T003021, end_date=20240412T003022
[2024-04-12T00:30:22.156+0000] {standard_task_runner.py:110} ERROR - Failed to execute job 69 for task touch_about_us (Bash command failed. The command returned a non-zero exit code 1.; 250)
[2024-04-12T00:30:22.209+0000] {local_task_job_runner.py:240} INFO - Task exited with return code 1
[2024-04-12T00:30:22.241+0000] {taskinstance.py:3482} INFO - 0 downstream tasks scheduled from follow-on schedule check
[2024-04-12T00:30:22.256+0000] {local_task_job_runner.py:222} INFO - ::endgroup::
