[2024-04-15T10:28:45.462+0000] {task_context_logger.py:104} ERROR - Executor reports task instance <TaskInstance: eksplorasii_dag.create_fruits_table scheduled__2023-10-15T00:00:00+00:00 [queued]> finished (failed) although the task says it's queued. (Info: None) Was the task killed externally?
