[2024-04-15T15:15:16.846+0000] {task_context_logger.py:104} WARNING - Marking task instance <TaskInstance: eksplorasii_dag.get_fruit_data manual__2024-04-15T14:47:59.932602+00:00 [queued]> stuck in queued as failed. If the task instance has available retries, it will be retried.
[2024-04-15T15:15:20.890+0000] {task_context_logger.py:104} ERROR - Executor reports task instance <TaskInstance: eksplorasii_dag.get_fruit_data manual__2024-04-15T14:47:59.932602+00:00 [queued]> finished (failed) although the task says it's queued. (Info: None) Was the task killed externally?
