[2024-04-12T00:26:11.736+0000] {local_task_job_runner.py:120} INFO - ::group::Pre task execution logs
[2024-04-12T00:26:11.962+0000] {taskinstance.py:2073} INFO - Dependencies all met for dep_context=non-requeueable deps ti=<TaskInstance: prioritas1_no1.touch_our_works scheduled__2024-04-11T00:00:00+00:00 [queued]>
[2024-04-12T00:26:11.975+0000] {taskinstance.py:2073} INFO - Dependencies all met for dep_context=requeueable deps ti=<TaskInstance: prioritas1_no1.touch_our_works scheduled__2024-04-11T00:00:00+00:00 [queued]>
[2024-04-12T00:26:11.976+0000] {taskinstance.py:2303} INFO - Starting attempt 3 of 6
[2024-04-12T00:26:12.180+0000] {taskinstance.py:2327} INFO - Executing <Task(BashOperator): touch_our_works> on 2024-04-11 00:00:00+00:00
[2024-04-12T00:26:12.242+0000] {warnings.py:110} WARNING - /home/***/.local/lib/python3.12/site-packages/***/task/task_runner/standard_task_runner.py:61: DeprecationWarning: This process (pid=154) is multi-threaded, use of fork() may lead to deadlocks in the child.
  pid = os.fork()

[2024-04-12T00:26:12.258+0000] {standard_task_runner.py:63} INFO - Started process 158 to run task
[2024-04-12T00:26:12.245+0000] {standard_task_runner.py:90} INFO - Running: ['***', 'tasks', 'run', 'prioritas1_no1', 'touch_our_works', 'scheduled__2024-04-11T00:00:00+00:00', '--job-id', '55', '--raw', '--subdir', 'DAGS_FOLDER/prioritas1_dag.py', '--cfg-path', '/tmp/tmpa1qxus0a']
[2024-04-12T00:26:12.273+0000] {standard_task_runner.py:91} INFO - Job 55: Subtask touch_our_works
[2024-04-12T00:26:12.481+0000] {task_command.py:426} INFO - Running <TaskInstance: prioritas1_no1.touch_our_works scheduled__2024-04-11T00:00:00+00:00 [running]> on host 805e8d5936d1
[2024-04-12T00:26:12.709+0000] {taskinstance.py:2644} INFO - Exporting env vars: AIRFLOW_CTX_DAG_OWNER='abdan' AIRFLOW_CTX_DAG_ID='prioritas1_no1' AIRFLOW_CTX_TASK_ID='touch_our_works' AIRFLOW_CTX_EXECUTION_DATE='2024-04-11T00:00:00+00:00' AIRFLOW_CTX_TRY_NUMBER='3' AIRFLOW_CTX_DAG_RUN_ID='scheduled__2024-04-11T00:00:00+00:00'
[2024-04-12T00:26:12.715+0000] {taskinstance.py:430} INFO - ::endgroup::
[2024-04-12T00:26:12.734+0000] {subprocess.py:63} INFO - Tmp dir root location: /tmp
[2024-04-12T00:26:12.736+0000] {subprocess.py:75} INFO - Running command: ['/usr/bin/bash', '-c', 'touch our_works/works.txt']
[2024-04-12T00:26:12.769+0000] {subprocess.py:86} INFO - Output:
[2024-04-12T00:26:12.809+0000] {subprocess.py:93} INFO - touch: cannot touch 'our_works/works.txt': No such file or directory
[2024-04-12T00:26:12.809+0000] {subprocess.py:97} INFO - Command exited with return code 1
[2024-04-12T00:26:12.811+0000] {taskinstance.py:441} INFO - ::group::Post task execution logs
[2024-04-12T00:26:12.829+0000] {taskinstance.py:2890} ERROR - Task failed with exception
Traceback (most recent call last):
  File "/home/airflow/.local/lib/python3.12/site-packages/airflow/models/taskinstance.py", line 465, in _execute_task
    result = _execute_callable(context=context, **execute_callable_kwargs)
             ^^^^^^^^^^^^^^^^^^^^^^^^^^^^^^^^^^^^^^^^^^^^^^^^^^^^^^^^^^^^^
  File "/home/airflow/.local/lib/python3.12/site-packages/airflow/models/taskinstance.py", line 432, in _execute_callable
    return execute_callable(context=context, **execute_callable_kwargs)
           ^^^^^^^^^^^^^^^^^^^^^^^^^^^^^^^^^^^^^^^^^^^^^^^^^^^^^^^^^^^^
  File "/home/airflow/.local/lib/python3.12/site-packages/airflow/models/baseoperator.py", line 400, in wrapper
    return func(self, *args, **kwargs)
           ^^^^^^^^^^^^^^^^^^^^^^^^^^^
  File "/home/airflow/.local/lib/python3.12/site-packages/airflow/operators/bash.py", line 243, in execute
    raise AirflowException(
airflow.exceptions.AirflowException: Bash command failed. The command returned a non-zero exit code 1.
[2024-04-12T00:26:12.856+0000] {taskinstance.py:1205} INFO - Marking task as UP_FOR_RETRY. dag_id=prioritas1_no1, task_id=touch_our_works, execution_date=20240411T000000, start_date=20240412T002611, end_date=20240412T002612
[2024-04-12T00:26:12.882+0000] {standard_task_runner.py:110} ERROR - Failed to execute job 55 for task touch_our_works (Bash command failed. The command returned a non-zero exit code 1.; 158)
[2024-04-12T00:26:12.937+0000] {local_task_job_runner.py:240} INFO - Task exited with return code 1
[2024-04-12T00:26:12.979+0000] {taskinstance.py:3482} INFO - 0 downstream tasks scheduled from follow-on schedule check
[2024-04-12T00:26:12.998+0000] {local_task_job_runner.py:222} INFO - ::endgroup::
