[2024-04-13T18:03:25.982+0000] {local_task_job_runner.py:120} INFO - ::group::Pre task execution logs
[2024-04-13T18:03:26.293+0000] {taskinstance.py:2073} INFO - Dependencies all met for dep_context=non-requeueable deps ti=<TaskInstance: fruits_data_pipeline.create_fruits_table manual__2024-04-13T17:37:53.418977+00:00 [queued]>
[2024-04-13T18:03:26.367+0000] {taskinstance.py:2073} INFO - Dependencies all met for dep_context=requeueable deps ti=<TaskInstance: fruits_data_pipeline.create_fruits_table manual__2024-04-13T17:37:53.418977+00:00 [queued]>
[2024-04-13T18:03:26.376+0000] {taskinstance.py:2303} INFO - Starting attempt 1 of 4
[2024-04-13T18:03:26.428+0000] {taskinstance.py:2327} INFO - Executing <Task(PythonOperator): create_fruits_table> on 2024-04-13 17:37:53.418977+00:00
[2024-04-13T18:03:26.580+0000] {warnings.py:110} WARNING - /home/***/.local/lib/python3.12/site-packages/***/task/task_runner/standard_task_runner.py:61: DeprecationWarning: This process (pid=60) is multi-threaded, use of fork() may lead to deadlocks in the child.
  pid = os.fork()

[2024-04-13T18:03:26.583+0000] {standard_task_runner.py:63} INFO - Started process 73 to run task
[2024-04-13T18:03:26.588+0000] {standard_task_runner.py:90} INFO - Running: ['***', 'tasks', 'run', 'fruits_data_pipeline', 'create_fruits_table', 'manual__2024-04-13T17:37:53.418977+00:00', '--job-id', '232', '--raw', '--subdir', 'DAGS_FOLDER/eksplorasii_dag.py', '--cfg-path', '/tmp/tmpaonv7d_t']
[2024-04-13T18:03:26.605+0000] {standard_task_runner.py:91} INFO - Job 232: Subtask create_fruits_table
[2024-04-13T18:03:28.913+0000] {task_command.py:426} INFO - Running <TaskInstance: fruits_data_pipeline.create_fruits_table manual__2024-04-13T17:37:53.418977+00:00 [running]> on host 2354a2c4893f
[2024-04-13T18:03:29.410+0000] {taskinstance.py:2644} INFO - Exporting env vars: AIRFLOW_CTX_DAG_OWNER='abdan' AIRFLOW_CTX_DAG_ID='fruits_data_pipeline' AIRFLOW_CTX_TASK_ID='create_fruits_table' AIRFLOW_CTX_EXECUTION_DATE='2024-04-13T17:37:53.418977+00:00' AIRFLOW_CTX_TRY_NUMBER='1' AIRFLOW_CTX_DAG_RUN_ID='manual__2024-04-13T17:37:53.418977+00:00'
[2024-04-13T18:03:29.416+0000] {taskinstance.py:430} INFO - ::endgroup::
[2024-04-13T18:03:29.429+0000] {taskinstance.py:441} INFO - ::group::Post task execution logs
[2024-04-13T18:03:29.436+0000] {taskinstance.py:2890} ERROR - Task failed with exception
Traceback (most recent call last):
  File "/home/airflow/.local/lib/python3.12/site-packages/airflow/models/taskinstance.py", line 465, in _execute_task
    result = _execute_callable(context=context, **execute_callable_kwargs)
             ^^^^^^^^^^^^^^^^^^^^^^^^^^^^^^^^^^^^^^^^^^^^^^^^^^^^^^^^^^^^^
  File "/home/airflow/.local/lib/python3.12/site-packages/airflow/models/taskinstance.py", line 432, in _execute_callable
    return execute_callable(context=context, **execute_callable_kwargs)
           ^^^^^^^^^^^^^^^^^^^^^^^^^^^^^^^^^^^^^^^^^^^^^^^^^^^^^^^^^^^^
  File "/home/airflow/.local/lib/python3.12/site-packages/airflow/models/baseoperator.py", line 400, in wrapper
    return func(self, *args, **kwargs)
           ^^^^^^^^^^^^^^^^^^^^^^^^^^^
  File "/home/airflow/.local/lib/python3.12/site-packages/airflow/operators/python.py", line 235, in execute
    return_value = self.execute_callable()
                   ^^^^^^^^^^^^^^^^^^^^^^^
  File "/home/airflow/.local/lib/python3.12/site-packages/airflow/operators/python.py", line 252, in execute_callable
    return self.python_callable(*self.op_args, **self.op_kwargs)
           ^^^^^^^^^^^^^^^^^^^^^^^^^^^^^^^^^^^^^^^^^^^^^^^^^^^^^
  File "/opt/airflow/dags/eksplorasii_dag.py", line 26, in create_fruits_table
    conn = psycopg2.connect(
           ^^^^^^^^^^^^^^^^^
  File "/home/airflow/.local/lib/python3.12/site-packages/psycopg2/__init__.py", line 122, in connect
    conn = _connect(dsn, connection_factory=connection_factory, **kwasync)
           ^^^^^^^^^^^^^^^^^^^^^^^^^^^^^^^^^^^^^^^^^^^^^^^^^^^^^^^^^^^^^^^
psycopg2.OperationalError: connection to server at "localhost" (::1), port 5432 failed: Connection refused
	Is the server running on that host and accepting TCP/IP connections?
connection to server at "localhost" (127.0.0.1), port 5432 failed: Connection refused
	Is the server running on that host and accepting TCP/IP connections?

[2024-04-13T18:03:29.493+0000] {taskinstance.py:1205} INFO - Marking task as UP_FOR_RETRY. dag_id=fruits_data_pipeline, task_id=create_fruits_table, execution_date=20240413T173753, start_date=20240413T180326, end_date=20240413T180329
[2024-04-13T18:03:29.538+0000] {standard_task_runner.py:110} ERROR - Failed to execute job 232 for task create_fruits_table (connection to server at "localhost" (::1), port 5432 failed: Connection refused
	Is the server running on that host and accepting TCP/IP connections?
connection to server at "localhost" (127.0.0.1), port 5432 failed: Connection refused
	Is the server running on that host and accepting TCP/IP connections?
; 73)
[2024-04-13T18:03:29.588+0000] {local_task_job_runner.py:240} INFO - Task exited with return code 1
[2024-04-13T18:03:29.606+0000] {warnings.py:110} WARNING - /home/***/.local/lib/python3.12/site-packages/***/models/baseoperator.py:1296: AirflowProviderDeprecationWarning: Call to deprecated class SimpleHttpOperator. (Class `SimpleHttpOperator` is deprecated and will be removed in a future release. Please use `HttpOperator` instead.)
  result = cls.__new__(cls)

[2024-04-13T18:03:29.662+0000] {taskinstance.py:3482} INFO - 0 downstream tasks scheduled from follow-on schedule check
[2024-04-13T18:03:29.682+0000] {local_task_job_runner.py:222} INFO - ::endgroup::
