[2024-04-11T13:24:39.359+0000] {task_context_logger.py:104} ERROR - Executor reports task instance <TaskInstance: prioritas2.print_success_message manual__2024-04-11T13:21:13.943726+00:00 [queued]> finished (failed) although the task says it's queued. (Info: None) Was the task killed externally?
