[2024-04-14T13:12:38.200+0000] {task_context_logger.py:104} ERROR - Executor reports task instance <TaskInstance: eksplorasi_data_ingestion.extract_task manual__2024-04-14T13:08:21.168246+00:00 [queued]> finished (failed) although the task says it's queued. (Info: None) Was the task killed externally?
