[2024-04-11T12:23:40.806+0000] {task_context_logger.py:104} ERROR - Executor reports task instance <TaskInstance: prioritas1_no2.generate_random_numbers scheduled__2024-04-10T00:00:00+00:00 [queued]> finished (failed) although the task says it's queued. (Info: None) Was the task killed externally?
