[2024-04-15T15:49:47.919+0000] {task_context_logger.py:104} ERROR - Executor reports task instance <TaskInstance: prioritas_1_no_2.generate_random_numbers scheduled__2024-04-14T00:00:00+00:00 [queued]> finished (failed) although the task says it's queued. (Info: None) Was the task killed externally?
