[2024-04-13T15:48:47.550+0000] {task_context_logger.py:104} ERROR - Executor reports task instance <TaskInstance: prioritas2.get_data_from_api scheduled__2024-04-12T00:00:00+00:00 [queued]> finished (failed) although the task says it's queued. (Info: None) Was the task killed externally?
